<?xml version="1.0" encoding="utf-8"?>
<!-- This URDF was automatically created by SolidWorks to URDF Exporter! Originally created by Stephen Brawner (brawner@gmail.com)
     Commit Version: 1.5.0-0-g9aa0fdb  Build Version: 1.5.7004.21443
     For more information, please see http://wiki.ros.org/sw_urdf_exporter -->
<robot name="quadruped_model_lh_leg">

  <link name="base">
    <inertial>
      <origin rpy="0 0 0" xyz="0.002284 -4.1e-05 0.025165"/>
      <mass value="13.733"/>
      <inertia ixx="0.073348887" ixy="0.00030338" ixz="0.001918218" iyy="0.250684593" iyz="-7.5402e-05" izz="0.254469458"/>
    </inertial>
  </link>
   <joint name="LH_HAA" type="revolute">
    <origin rpy="0 0 0" xyz="-0.21935 0.0875 0"/>
    <parent link="base"/>
    <child link="LH_HIP"/>
    <axis xyz="1 0 0"/>
    <dynamics damping="0" friction="0"/>
    <limit effort="20" lower="-0.872664625997" upper="1.0471975512" velocity="52.4"/>
  </joint>
  <link name="LH_HIP">
    <inertial>
      <origin rpy="0 0 0" xyz="0.001568 -0.008134 0.000864"/>
      <mass value="1.096"/>
      <inertia ixx="0.000822113" ixy="4.982e-06" ixz="3.672e-05" iyy="0.000983196" iyz="2.811e-06" izz="0.000864753"/>
    </inertial>
  </link>
  <joint name="LH_HFE" type="revolute">
    <origin rpy="0 0 0" xyz="0 0.037 0"/>
    <parent link="LH_HIP"/>
    <child link="LH_THIGH"/>
    <axis xyz="0 1 0"/>
    <dynamics damping="0" friction="0"/>
    <limit effort="55" lower="-0.523598775598" upper="3.92699081699" velocity="28.6"/>
  </joint>
  <link name="LH_THIGH">
    <inertial>
      <origin rpy="0 0 0" xyz="-0.000482 0.02001 -0.031996"/>
      <mass value="1.528"/>
      <inertia ixx="0.00991611" ixy="1.0388e-05" ixz="0.000250428" iyy="0.009280083" iyz="-8.511e-05" izz="0.00178256"/>
    </inertial>
  </link>
  <joint name="LH_KFE" type="revolute">
    <origin rpy="0 0 0" xyz="0 0 -0.25"/>
    <parent link="LH_THIGH"/>
    <child link="LH_SHANK"/>
    <axis xyz="0 1 0"/>
    <dynamics damping="0" friction="0"/>
    <limit effort="55" lower="-2.77507351067" upper="-0.610865238198" velocity="28.6"/>
  </joint>
  <link name="LH_SHANK">
    <inertial>
      <origin rpy="0 0 0" xyz="-0.002196 -0.000381 -0.12338"/>
      <mass value="0.241"/>
      <inertia ixx="0.006181961" ixy="2.37e-07" ixz="-2.985e-06" iyy="0.006196546" iyz="5.138e-06" izz="3.4774e-05"/>
    </inertial>
  </link>
  <joint name="LH_ADAPTER" type="fixed">
    <origin rpy="0 0 0" xyz="0 0 -0.25"/>
    <parent link="LH_SHANK"/>
    <child link="LH_FOOT"/>
  </joint>
  <link name="LH_FOOT">
    <inertial>
      <mass value="0.06"/>
      <inertia ixx="1.6854e-05" ixy="0.0" ixz="0.0" iyy="1.6854e-05" iyz="0.0" izz="1.6854e-05"/>
    </inertial>
  </link>
</robot>
